Workbook

Sheet Paramètres
A3: Capacité cuve (L) | B3: 18000
A4: Niveau sécurité (%) | B4: 0.1
A5: Stock initial (L) | B5: 12000
A6: Seuil sécurité (L) | B6: =B3*B4

Sheet Commandes
A1: Date | B1: N° Châssis | C1: Montant | D1: PU | E1: Quantité livrée (L) | F1: Stock initial (L) | G1: Quantité vendue (L) | H1: Stock final (L) | I1: Alerte
E2: =IFERROR(C2/D2,0) | F2: =Paramètres!B5 | G2: =IFERROR(SUMIF(Ventes!A:A,A2,Ventes!B:B),0) | H2: =MAX(0,F2+E2-G2) | I2: =IF(H2<Paramètres!B6,"ALERTE","OK")
E3: =IFERROR(C3/D3,0) | F3: =H2 | G3: =IFERROR(SUMIF(Ventes!A:A,A3,Ventes!B:B),0) | H3: =MAX(0,F3+E3-G3) | I3: =IF(H3<Paramètres!B6,"ALERTE","OK")
E4: =IFERROR(C4/D4,0) | F4: =H3 | G4: =IFERROR(SUMIF(Ventes!A:A,A4,Ventes!B:B),0) | H4: =MAX(0,F4+E4-G4) | I4: =IF(H4<Paramètres!B6,"ALERTE","OK")
E5: =IFERROR(C5/D5,0) | F5: =H4 | G5: =IFERROR(SUMIF(Ventes!A:A,A5,Ventes!B:B),0) | H5: =MAX(0,F5+E5-G5) | I5: =IF(H5<Paramètres!B6,"ALERTE","OK")
E6: =IFERROR(C6/D6,0) | F6: =H5 | G6: =IFERROR(SUMIF(Ventes!A:A,A6,Ventes!B:B),0) | H6: =MAX(0,F6+E6-G6) | I6: =IF(H6<Paramètres!B6,"ALERTE","OK")
E7: =IFERROR(C7/D7,0) | F7: =H6 | G7: =IFERROR(SUMIF(Ventes!A:A,A7,Ventes!B:B),0) | H7: =MAX(0,F7+E7-G7) | I7: =IF(H7<Paramètres!B6,"ALERTE","OK")
E8: =IFERROR(C8/D8,0) | F8: =H7 | G8: =IFERROR(SUMIF(Ventes!A:A,A8,Ventes!B:B),0) | H8: =MAX(0,F8+E8-G8) | I8: =IF(H8<Paramètres!B6,"ALERTE","OK")
E9: =IFERROR(C9/D9,0) | F9: =H8 | G9: =IFERROR(SUMIF(Ventes!A:A,A9,Ventes!B:B),0) | H9: =MAX(0,F9+E9-G9) | I9: =IF(H9<Paramètres!B6,"ALERTE","OK")
E10: =IFERROR(C10/D10,0) | F10: =H9 | G10: =IFERROR(SUMIF(Ventes!A:A,A10,Ventes!B:B),0) | H10: =MAX(0,F10+E10-G10) | I10: =IF(H10<Paramètres!B6,"ALERTE","OK")
E11: =IFERROR(C11/D11,0) | F11: =H10 | G11: =IFERROR(SUMIF(Ventes!A:A,A11,Ventes!B:B),0) | H11: =MAX(0,F11+E11-G11) | I11: =IF(H11<Paramètres!B6,"ALERTE","OK")
E12: =IFERROR(C12/D12,0) | F12: =H11 | G12: =IFERROR(SUMIF(Ventes!A:A,A12,Ventes!B:B),0) | H12: =MAX(0,F12+E12-G12) | I12: =IF(H12<Paramètres!B6,"ALERTE","OK")
E13: =IFERROR(C13/D13,0) | F13: =H12 | G13: =IFERROR(SUMIF(Ventes!A:A,A13,Ventes!B:B),0) | H13: =MAX(0,F13+E13-G13) | I13: =IF(H13<Paramètres!B6,"ALERTE","OK")
E14: =IFERROR(C14/D14,0) | F14: =H13 | G14: =IFERROR(SUMIF(Ventes!A:A,A14,Ventes!B:B),0) | H14: =MAX(0,F14+E14-G14) | I14: =IF(H14<Paramètres!B6,"ALERTE","OK")
E15: =IFERROR(C15/D15,0) | F15: =H14 | G15: =IFERROR(SUMIF(Ventes!A:A,A15,Ventes!B:B),0) | H15: =MAX(0,F15+E15-G15) | I15: =IF(H15<Paramètres!B6,"ALERTE","OK")
E16: =IFERROR(C16/D16,0) | F16: =H15 | G16: =IFERROR(SUMIF(Ventes!A:A,A16,Ventes!B:B),0) | H16: =MAX(0,F16+E16-G16) | I16: =IF(H16<Paramètres!B6,"ALERTE","OK")
E17: =IFERROR(C17/D17,0) | F17: =H16 | G17: =IFERROR(SUMIF(Ventes!A:A,A17,Ventes!B:B),0) | H17: =MAX(0,F17+E17-G17) | I17: =IF(H17<Paramètres!B6,"ALERTE","OK")
E18: =IFERROR(C18/D18,0) | F18: =H17 | G18: =IFERROR(SUMIF(Ventes!A:A,A18,Ventes!B:B),0) | H18: =MAX(0,F18+E18-G18) | I18: =IF(H18<Paramètres!B6,"ALERTE","OK")
E19: =IFERROR(C19/D19,0) | F19: =H18 | G19: =IFERROR(SUMIF(Ventes!A:A,A19,Ventes!B:B),0) | H19: =MAX(0,F19+E19-G19) | I19: =IF(H19<Paramètres!B6,"ALERTE","OK")
E20: =IFERROR(C20/D20,0) | F20: =H19 | G20: =IFERROR(SUMIF(Ventes!A:A,A20,Ventes!B:B),0) | H20: =MAX(0,F20+E20-G20) | I20: =IF(H20<Paramètres!B6,"ALERTE","OK")
E21: =IFERROR(C21/D21,0) | F21: =H20 | G21: =IFERROR(SUMIF(Ventes!A:A,A21,Ventes!B:B),0) | H21: =MAX(0,F21+E21-G21) | I21: =IF(H21<Paramètres!B6,"ALERTE","OK")
E22: =IFERROR(C22/D22,0) | F22: =H21 | G22: =IFERROR(SUMIF(Ventes!A:A,A22,Ventes!B:B),0) | H22: =MAX(0,F22+E22-G22) | I22: =IF(H22<Paramètres!B6,"ALERTE","OK")
E23: =IFERROR(C23/D23,0) | F23: =H22 | G23: =IFERROR(SUMIF(Ventes!A:A,A23,Ventes!B:B),0) | H23: =MAX(0,F23+E23-G23) | I23: =IF(H23<Paramètres!B6,"ALERTE","OK")
E24: =IFERROR(C24/D24,0) | F24: =H23 | G24: =IFERROR(SUMIF(Ventes!A:A,A24,Ventes!B:B),0) | H24: =MAX(0,F24+E24-G24) | I24: =IF(H24<Paramètres!B6,"ALERTE","OK")
E25: =IFERROR(C25/D25,0) | F25: =H24 | G25: =IFERROR(SUMIF(Ventes!A:A,A25,Ventes!B:B),0) | H25: =MAX(0,F25+E25-G25) | I25: =IF(H25<Paramètres!B6,"ALERTE","OK")
E26: =IFERROR(C26/D26,0) | F26: =H25 | G26: =IFERROR(SUMIF(Ventes!A:A,A26,Ventes!B:B),0) | H26: =MAX(0,F26+E26-G26) | I26: =IF(H26<Paramètres!B6,"ALERTE","OK")
E27: =IFERROR(C27/D27,0) | F27: =H26 | G27: =IFERROR(SUMIF(Ventes!A:A,A27,Ventes!B:B),0) | H27: =MAX(0,F27+E27-G27) | I27: =IF(H27<Paramètres!B6,"ALERTE","OK")
E28: =IFERROR(C28/D28,0) | F28: =H27 | G28: =IFERROR(SUMIF(Ventes!A:A,A28,Ventes!B:B),0) | H28: =MAX(0,F28+E28-G28) | I28: =IF(H28<Paramètres!B6,"ALERTE","OK")
E29: =IFERROR(C29/D29,0) | F29: =H28 | G29: =IFERROR(SUMIF(Ventes!A:A,A29,Ventes!B:B),0) | H29: =MAX(0,F29+E29-G29) | I29: =IF(H29<Paramètres!B6,"ALERTE","OK")
E30: =IFERROR(C30/D30,0) | F30: =H29 | G30: =IFERROR(SUMIF(Ventes!A:A,A30,Ventes!B:B),0) | H30: =MAX(0,F30+E30-G30) | I30: =IF(H30<Paramètres!B6,"ALERTE","OK")
E31: =IFERROR(C31/D31,0) | F31: =H30 | G31: =IFERROR(SUMIF(Ventes!A:A,A31,Ventes!B:B),0) | H31: =MAX(0,F31+E31-G31) | I31: =IF(H31<Paramètres!B6,"ALERTE","OK")
E32: =IFERROR(C32/D32,0) | F32: =H31 | G32: =IFERROR(SUMIF(Ventes!A:A,A32,Ventes!B:B),0) | H32: =MAX(0,F32+E32-G32) | I32: =IF(H32<Paramètres!B6,"ALERTE","OK")
E33: =IFERROR(C33/D33,0) | F33: =H32 | G33: =IFERROR(SUMIF(Ventes!A:A,A33,Ventes!B:B),0) | H33: =MAX(0,F33+E33-G33) | I33: =IF(H33<Paramètres!B6,"ALERTE","OK")
E34: =IFERROR(C34/D34,0) | F34: =H33 | G34: =IFERROR(SUMIF(Ventes!A:A,A34,Ventes!B:B),0) | H34: =MAX(0,F34+E34-G34) | I34: =IF(H34<Paramètres!B6,"ALERTE","OK")
E35: =IFERROR(C35/D35,0) | F35: =H34 | G35: =IFERROR(SUMIF(Ventes!A:A,A35,Ventes!B:B),0) | H35: =MAX(0,F35+E35-G35) | I35: =IF(H35<Paramètres!B6,"ALERTE","OK")
E36: =IFERROR(C36/D36,0) | F36: =H35 | G36: =IFERROR(SUMIF(Ventes!A:A,A36,Ventes!B:B),0) | H36: =MAX(0,F36+E36-G36) | I36: =IF(H36<Paramètres!B6,"ALERTE","OK")
E37: =IFERROR(C37/D37,0) | F37: =H36 | G37: =IFERROR(SUMIF(Ventes!A:A,A37,Ventes!B:B),0) | H37: =MAX(0,F37+E37-G37) | I37: =IF(H37<Paramètres!B6,"ALERTE","OK")
E38: =IFERROR(C38/D38,0) | F38: =H37 | G38: =IFERROR(SUMIF(Ventes!A:A,A38,Ventes!B:B),0) | H38: =MAX(0,F38+E38-G38) | I38: =IF(H38<Paramètres!B6,"ALERTE","OK")
E39: =IFERROR(C39/D39,0) | F39: =H38 | G39: =IFERROR(SUMIF(Ventes!A:A,A39,Ventes!B:B),0) | H39: =MAX(0,F39+E39-G39) | I39: =IF(H39<Paramètres!B6,"ALERTE","OK")
E40: =IFERROR(C40/D40,0) | F40: =H39 | G40: =IFERROR(SUMIF(Ventes!A:A,A40,Ventes!B:B),0) | H40: =MAX(0,F40+E40-G40) | I40: =IF(H40<Paramètres!B6,"ALERTE","OK")
...

Sheet Ventes
A1: Date | B1: Quantité vendue (L) | C1: Montant encaissé
